Workbook

Sheet Summary
A1: CHIPOTLE MEXICAN GRILL (NYSE: CMG) - DCF VALUATION SUMMARY
A2: OUTPUT | One-page valuation conclusion. Every figure links to the supporting tabs - nothing here is typed.
A4: VALUATION CONCLUSION
A5: Implied share price (DCF) | B5: $ | C5: ='Valuation Bridge'!C13
A6: Current market price | B6: $ | C6: ='Valuation Bridge'!C16 | I6: stockanalysis.com/stocks/cmg/, closing price 2026-09-04 (last completed session); retrieved 2026-09-06.
A7: Implied upside / (downside) | B7: % | C7: ='Valuation Bridge'!C17
A8: Implied enterprise value | B8: $mm | C8: ='Valuation Bridge'!C7
A9: Implied equity value | B9: $mm | C9: ='Valuation Bridge'!C11
A10: Verdict | C10: ='Valuation Bridge'!C18
A12: KEY ASSUMPTIONS
A13: Revenue CAGR, FY2025A-FY2030E | B13: % | C13: =Assumptions!G20 | I13: Driven by unit growth of ~7%/yr plus low-single-digit AUV growth.
A14: Restaurants at FY2030E | B14: # | C14: =Assumptions!G11 | I14: From 4,042 at FY2025A. Long-term company goal is 7,000 in the U.S. and Canada.
A15: EBIT margin, FY2026E (trough) | B15: % | C15: =Assumptions!C25
A16: Terminal EBIT margin, FY2030E | B16: % | C16: =Assumptions!G25 | I16: Recovers to the FY2025A level; still below the FY2024A peak of 16.9%.
A17: Effective tax rate | B17: % | C17: =Assumptions!C29
A18: WACC | B18: % | C18: =WACC!C28 | I18: Equals the cost of equity - Chipotle has no debt.
A19: Terminal growth rate | B19: % | C19: =Assumptions!C38
A20: Terminal value as % of enterprise value | B20: % | C20: ='Terminal Value'!C47
A21: Implied exit EV/EBITDA (from the Gordon Growth TV) | B21: x | C21: ='Terminal Value'!C32
A22: CMG's current EV / LTM EBITDA | B22: x | C22: =WACC!C47
A24: VALUATION CONCLUSION - THREE SENTENCES
A25: 1. | C25: ="On a units-times-AUV revenue build reaching "&TEXT(C14,"#,##0")&" restaurants by FY2030E, an EBIT margin that troughs at "&TEXT(C15,"0.0%")&" in FY2026E before recovering to "&TEXT(C16,"0.0%")&", a "&TEXT(C18,"0.00%")&" WACC and "&TEXT(C19,"0.00%")&" terminal growth, the model produces an implied value of "&TEXT(C5,"$#,##0.00")&" per share against a market price of "&TEXT(C6,"$#,##0.00")&", or "&TEXT(C7,"0.0%")&"."
A26: 2. | C26: ="The gap is not an arithmetic error: it is the growth premium in the share price. The Gordon Growth terminal value implies an exit multiple of only "&TEXT(C21,"0.0")&"x EBITDA against the "&TEXT(C22,"0.0")&"x CMG trades at today, so the market is embedding either a materially lower discount rate or long-run growth well above nominal GDP."
A27: 3. | C27: ="With "&TEXT(C20,"0%")&" of enterprise value sitting in the terminal value, the conclusion is a statement about the discount rate and terminal assumptions rather than about the five forecast years - which is why the Sensitivity tab, not the base case, is the real output of this model."
A29: HOW TO READ THIS WORKBOOK
A30: Font convention: BLUE = hardcoded input BLACK = formula on this sheet GREEN = link to another sheet.
A31: Tab colours: BLUE tabs are inputs (Historicals, Assumptions). ORANGE tabs are calculations (WACC, DCF, Terminal Value). GREEN tabs are outputs (Summary, Valuation Bridge, Sensitivity).
A32: Every input cell carries a source note in column I. No number in this workbook is unsourced.
A33: Trace any figure by clicking it and pressing Ctrl+[ (Windows) or Ctrl+Alt+[ (Mac) to jump to its precedents.

Sheet Historicals
A1: HISTORICALS - FY2021A to FY2025A (as reported)
A2: INPUT | Actuals from Chipotle's 10-K filings. Blue = as filed. Black = computed margins and ratios that ground the forecast.
B4: Units | C4: FY2021A | D4: FY2022A | E4: FY2023A | F4: FY2024A | G4: FY2025A | I4: Source / note
A5: INCOME STATEMENT ($ in millions, as reported)
A6: Total revenue | B6: $mm | C6: 7547.061 | D6: 8634.652 | E6: 9871.649 | F6: 11313.853 | G6: 11925.601 | I6: FY2025 10-K (filed 2026-02-04, accn 0001058090-26-000009) Consolidated Statements of Income for FY2023-25; FY2023 10-K (filed 2024-02-08, accn 0001562762-24-000023) for FY2021-22
A7: Restaurant operating costs (exclusive of D&A shown separately):
A8: Food, beverage and packaging | B8: $mm | C8: 2308.631 | D8: 2602.245 | E8: 2912.564 | F8: 3374.516 | G8: 3526.992 | I8: FY2025 10-K Consolidated Statements of Income (FY23-25); FY2023 10-K (FY21-22)
A9: Labor | B9: $mm | C9: 1917.761 | D9: 2197.958 | E9: 2440.982 | F9: 2789.789 | G9: 2991.68 | I9: FY2025 10-K Consolidated Statements of Income (FY23-25); FY2023 10-K (FY21-22)
A10: Occupancy | B10: $mm | C10: 416.606 | D10: 460.425 | E10: 503.264 | F10: 563.374 | G10: 624.898 | I10: FY2025 10-K Consolidated Statements of Income (FY23-25); FY2023 10-K (FY21-22)
A11: Other operating costs | B11: $mm | C11: 1197.054 | D11: 1311.905 | E11: 1428.747 | F11: 1568.482 | G11: 1755.824 | I11: FY2025 10-K Consolidated Statements of Income (FY23-25); FY2023 10-K (FY21-22)
A12: Total restaurant operating costs | B12: $mm | C12: =C8+C9+C10+C11 | D12: =D8+D9+D10+D11 | E12: =E8+E9+E10+E11 | F12: =F8+F9+F10+F11 | G12: =G8+G9+G10+G11 | I12: Sum of the four restaurant operating cost lines above.
A13: General and administrative expenses | B13: $mm | C13: 606.854 | D13: 564.191 | E13: 633.584 | F13: 697.483 | G13: 652.017 | I13: FY2025 10-K Consolidated Statements of Income (FY23-25); FY2023 10-K (FY21-22)
A14: Depreciation and amortization | B14: $mm | C14: 254.657 | D14: 286.826 | E14: 319.394 | F14: 335.03 | G14: 361.382 | I14: FY2025 10-K Consolidated Statements of Income and Statements of Cash Flows (FY23-25); FY2023 10-K (FY21-22)
A15: Pre-opening costs | B15: $mm | C15: 21.264 | D15: 29.56 | E15: 36.931 | F15: 41.897 | G15: 49.507 | I15: FY2025 10-K Consolidated Statements of Income (FY23-25); FY2023 10-K (FY21-22)
A16: Impairment, closure costs, and asset disposals | B16: $mm | C16: 19.291 | D16: 21.139 | E16: 38.37 | F16: 26.949 | G16: 27.503 | I16: FY2025 10-K Consolidated Statements of Income (FY23-25); FY2023 10-K (FY21-22)
A17: Total operating expenses | B17: $mm | C17: =C12+C13+C14+C15+C16 | D17: =D12+D13+D14+D15+D16 | E17: =E12+E13+E14+E15+E16 | F17: =F12+F13+F14+F15+F16 | G17: =G12+G13+G14+G15+G16 | I17: Total restaurant operating costs + G&A + D&A + pre-opening + impairment.
A18: Operating income (EBIT) | B18: $mm | C18: =C6-C17 | D18: =D6-D17 | E18: =E6-E17 | F18: =F6-F17 | G18: =G6-G17 | I18: Total revenue less total operating expenses.
A19: Memo: EBIT as reported in the 10-K | B19: $mm | C19: 804.943 | D19: 1160.403 | E19: 1557.813 | F19: 1916.333 | G19: 1935.798 | I19: SEC XBRL companyfacts us-gaap:OperatingIncomeLoss, retrieved 2026-09-06; agrees to 10-K income statements
A20: Check: build vs. reported (must be 0.0) | B20: $mm | C20: =C18-C19 | D20: =D18-D19 | E20: =E18-E19 | F20: =F18-F19 | G20: =G18-G19 | I20: Tie-out. Any non-zero value means a cost line was mistyped.
A21: EBITDA (EBIT + D&A) | B21: $mm | C21: =C18+C14 | D21: =D18+D14 | E21: =E18+E14 | F21: =F18+F14 | G21: =G18+G14 | I21: Chipotle reports D&A as a separate line, so EBITDA = EBIT + D&A.
A22: Income before income taxes | B22: $mm | C22: 812.763 | D22: 1181.531 | E22: 1620.506 | F22: 2010.23 | G22: 2009.519 | I22: SEC XBRL companyfacts us-gaap:IncomeLossFromContinuingOperationsBeforeIncomeTaxes..., retrieved 2026-09-06
A23: Provision for income taxes | B23: $mm | C23: 159.779 | D23: 282.43 | E23: 391.769 | F23: 476.12 | G23: 473.758 | I23: SEC XBRL companyfacts us-gaap:IncomeTaxExpenseBenefit, retrieved 2026-09-06
A24: Effective income tax rate (as reported) | B24: % | C24: 0.197 | D24: 0.239 | E24: 0.242 | F24: 0.237 | G24: 0.236 | I24: FY2025 10-K Note 8 Income Taxes rate reconciliation (FY24-25); SEC XBRL us-gaap:EffectiveIncomeTaxRateContinuingOperations (FY21-23), retrieved 2026-09-06
A25: Effective tax rate (check: provision / pre-tax income) | B25: % | C25: =C23/C22 | D25: =D23/D22 | E25: =E23/E22 | F25: =F23/F22 | G25: =G23/G22 | I25: Recomputed from the two lines above.
A27: COMMON-SIZE: EVERY COST LINE AS A % OF REVENUE (this is what anchors the forecast)
A28: Food, beverage and packaging | B28: % rev | C28: =C8/C6 | D28: =D8/D6 | E28: =E8/E6 | F28: =F8/F6 | G28: =G8/G6
A29: Labor | B29: % rev | C29: =C9/C6 | D29: =D9/D6 | E29: =E9/E6 | F29: =F9/F6 | G29: =G9/G6
A30: Occupancy | B30: % rev | C30: =C10/C6 | D30: =D10/D6 | E30: =E10/E6 | F30: =F10/F6 | G30: =G10/G6
A31: Other operating costs | B31: % rev | C31: =C11/C6 | D31: =D11/D6 | E31: =E11/E6 | F31: =F11/F6 | G31: =G11/G6
A32: Total restaurant operating costs | B32: % rev | C32: =C12/C6 | D32: =D12/D6 | E32: =E12/E6 | F32: =F12/F6 | G32: =G12/G6
A33: General and administrative | B33: % rev | C33: =C13/C6 | D33: =D13/D6 | E33: =E13/E6 | F33: =F13/F6 | G33: =G13/G6
A34: Depreciation and amortization | B34: % rev | C34: =C14/C6 | D34: =D14/D6 | E34: =E14/E6 | F34: =F14/F6 | G34: =G14/G6
A35: Pre-opening costs | B35: % rev | C35: =C15/C6 | D35: =D15/D6 | E35: =E15/E6 | F35: =F15/F6 | G35: =G15/G6
A36: Impairment and closures | B36: % rev | C36: =C16/C6 | D36: =D16/D6 | E36: =E16/E6 | F36: =F16/F6 | G36: =G16/G6
A37: EBIT margin | B37: % rev | C37: =C18/C6 | D37: =D18/D6 | E37: =E18/E6 | F37: =F18/F6 | G37: =G18/G6 | I37: The single most important historical series in the model - the Assumptions tab EBIT margin path is set against it.
A38: EBITDA margin | B38: % rev | C38: =C21/C6 | D38: =D21/D6 | E38: =E21/E6 | F38: =F21/F6 | G38: =G21/G6
A39: Revenue growth (YoY) | B39: % | D39: =D6/C6-1 | E39: =E6/D6-1 | F39: =F6/E6-1 | G39: =G6/F6-1
A41: CASH FLOW ITEMS ($ in millions, from the consolidated statements of cash flows)
A42: Net cash provided by operating activities | B42: $mm | C42: 1282.113 | D42: 1323.179 | E42: 1783.477 | F42: 2105.076 | G42: 2113.926 | I42: FY2025 10-K Consolidated Statements of Cash Flows (FY23-25); FY2023 10-K (FY21-22)
A43: Capital expenditures (leasehold improvements, PP&E) | B43: $mm | C43: 442.475 | D43: 479.164 | E43: 560.731 | F43: 593.603 | G43: 666.336 | I43: FY2025 10-K Consolidated Statements of Cash Flows, investing activities (FY23-25); FY2023 10-K (FY21-22)
...

Sheet Assumptions
A1: ASSUMPTIONS - FY2026E to FY2030E forecast drivers
A2: INPUT | Every forward-looking driver in the model. Blue cells are the only things you change. Revenue is built units x AUV, not a top-line growth rate.
B4: Units | C4: FY2026E | D4: FY2027E | E4: FY2028E | F4: FY2029E | G4: FY2030E | I4: Source / note
A5: BLUE = hardcoded assumption (the only cells you should change). BLACK = formula on this sheet. GREEN = link to another sheet.
A7: REVENUE BUILD - restaurant count x AUV (never a blunt top-line growth rate)
A8: Restaurants - beginning of period | B8: # | C8: =Historicals!G87 | D8: =C11 | E8: =D11 | F8: =E11 | G8: =F11 | I8: FY2026E opens from the FY2025A closing count of 4,042 on the Historicals tab.
A9: New restaurant openings | B9: # | C9: 347 | D9: 355 | E9: 360 | F9: 365 | G9: 370 | I9: FY2025 10-K MD&A: 'We expect to open approximately 350 to 370 restaurants in 2026, which includes 10 to 15 international partner-operated restaurants.' Midpoint 360 less ~13 partner-operated = 347 company-owned in FY2026. FY2027-30 held roughly flat to modestly up, consistent with the FY2021-25 trend (215 / 236 / 271 / 304 / 334) and the stated long-term goal of 7,000 restaurants in the U.S. and Canada.
A10: Closures and relocations | B10: # | C10: -18 | D10: -18 | E10: -18 | F10: -18 | G10: -18 | I10: FY2021-25 permanent closures plus relocations averaged 17/yr (17, 15, 21, 15, 18 per the 10-K Restaurant Activity tables). Held at 18/yr.
A11: Restaurants - end of period | B11: # | C11: =C8+C9+C10 | D11: =D8+D9+D10 | E11: =E8+E9+E10 | F11: =F8+F9+F10 | G11: =G8+G9+G10
A12: Unit growth (YoY) | B12: % | C12: =C11/Historicals!G87-1 | D12: =D11/C11-1 | E12: =E11/D11-1 | F12: =F11/E11-1 | G12: =G11/F11-1
A13: Average restaurants during the period | B13: # | C13: =(C8+C11)/2 | D13: =(D8+D11)/2 | E13: =(E8+E11)/2 | F13: =(F8+F11)/2 | G13: =(G8+G11)/2
A15: AUV growth (YoY) | B15: % | C15: 0 | D15: 0.015 | E15: 0.02 | F15: 0.025 | G15: 0.025 | I15: FY2026: flat. Management guides FY2026 comparable restaurant sales to 'be about flat' (FY2025 10-K MD&A); H1 2026 revenue of $6,436.8m (Q2 2026 10-Q) is +8.4% YoY against ~8.5% average-unit growth, implying AUV roughly flat. FY2027-30: 1.5% rising to 2.5%, i.e. menu pricing of ~2-3% (FY2025 menu price increase was 2.1%) partly offset by continued new-unit AUV dilution. Note AUV growth runs below comps in expansion years because the denominator includes lower-volume new units.
A16: Average restaurant sales (AUV) | B16: $mm | C16: =Historicals!G92*(1+C15) | D16: =C16*(1+D15) | E16: =D16*(1+E15) | F16: =E16*(1+F15) | G16: =F16*(1+G15) | I16: Grown off the FY2025A AUV of $3.104m on the Historicals tab.
A17: Revenue realisation factor | B17: x | C17: 0.9867 | I17: Computed as the FY2023-FY2025 average of [reported revenue / (average units x AUV)]: 0.988 (2023), 0.983 (2024), 0.989 (2025). Calibration input; see the Historicals tab where it is computed from filed figures.
A18: TOTAL REVENUE | B18: $mm | C18: =C13*C16*$C$17 | D18: =D13*D16*$C$17 | E18: =E13*E16*$C$17 | F18: =F13*F16*$C$17 | G18: =G13*G16*$C$17 | I18: Average units x AUV x realisation factor. This is the only revenue line in the model; the DCF tab links to it.
A19: Revenue growth (YoY) | B19: % | C19: =C18/Historicals!G6-1 | D19: =D18/C18-1 | E19: =E18/D18-1 | F19: =F18/E18-1 | G19: =G18/F18-1
A20: Memo: FY2025A-FY2030E revenue CAGR | B20: % | G20: =(G18/Historicals!G6)^(1/5)-1
A21: Memo: comparable restaurant sales growth (context only) | B21: % | C21: 0 | D21: 0.015 | E21: 0.02 | F21: 0.025 | G21: 0.025 | I21: Disclosed as context, not as the revenue driver. FY2026 'about flat' per FY2025 10-K MD&A. History: +19.3% (2021), +8.0% (2022), +7.9% (2023), +7.4% (2024), -1.7% (2025).
A23: MARGIN PATH
A24: STATED POSITION: near-term COMPRESSION, then partial recovery - not expansion. FY2025A was 16.2% and H1 2026 ran at 14.3%. The forecast troughs at 14.5% in FY2026E and recovers to 16.3% by FY2030E, back to the FY2025A level but still below the FY2024A peak of 16.9%.
A25: EBIT margin | B25: % rev | C25: 0.145 | D25: 0.15 | E25: 0.155 | F25: 0.16 | G25: 0.163 | I25: PATH: compression then partial recovery - NOT a straight-line expansion. Actuals: 10.7% (2021), 13.4% (2022), 15.8% (2023), 16.9% (2024), 16.2% (2025). H1 2026 operating margin was 14.3% ($922.7m on $6,436.8m, Q2 2026 10-Q) versus 17.5% in H1 2025, so FY2026 is set at 14.5%. FY2027-30 recover to 16.3% - back to the FY2025 level but still below the FY2024 peak of 16.9% - as the tariff impact on food, beverage and packaging costs flagged in the FY2025 10-K normalises and comps return to positive territory. Terminal margin = 16.3%.
A26: Memo: FY2021A-FY2025A actual EBIT margin | B26: % rev | C26: =Historicals!C37 | D26: =Historicals!D37 | E26: =Historicals!E37 | F26: =Historicals!F37 | G26: =Historicals!G37 | I26: Direct link to the Historicals tab so the assumption sits next to the trend.
A28: TAX, CAPITAL INTENSITY AND WORKING CAPITAL
A29: Effective tax rate | B29: % | C29: 0.24 | I29: FY2022-FY2025 reported effective rates averaged 23.9% (23.9% / 24.2% / 23.7% / 23.6%; FY2025 10-K Note 8). FY2021's 19.7% is excluded as it was inflated by unusually large excess tax benefits on equity compensation. Rounded to 24.0%.
A30: D&A as % of revenue | B30: % rev | C30: 0.031 | D30: 0.031 | E30: 0.031 | F30: 0.031 | G30: 0.031 | I30: D&A / revenue: 3.4% (2021), 3.3% (2022), 3.2% (2023), 3.0% (2024), 3.0% (2025); H1 2026 = 3.0%. Held at 3.1% - slightly above the most recent year, reflecting the heavier fixed-asset base being built (Chipotlanes, kitchen automation).
A31: CapEx as % of revenue | B31: % rev | C31: 0.065 | D31: 0.062 | E31: 0.06 | F31: 0.058 | G31: 0.056 | I31: FY2026 is guided: 'In 2026, we expect to incur about $834.1 million in total capital expenditures' (FY2025 10-K MD&A), which is ~6.5% of forecast FY2026 revenue. Build cost is disclosed at ~$1.5m gross / ~$1.3m net of landlord reimbursements per new restaurant. FY2027-30 step down to 5.6% as absolute openings flatten against a larger revenue base. Actual capex/revenue: 5.9% (2021), 5.5% (2022), 5.7% (2023), 5.2% (2024), 5.6% (2025).
A32: Memo: implied FY2026E capex vs. the $834.1m guided | B32: $mm | C32: =C31*C18 | I32: FY2025 10-K MD&A: 'In 2026, we expect to incur about $834.1 million in total capital expenditures.' This row should land close to that number.
A33: Change in NWC as % of change in revenue (+ = cash SOURCE) | B33: % | C33: 0.005 | I33: POSITIVE = cash SOURCE. Computed from the 10-K cash flow statements as the sum of the AR, inventory, prepaid, other assets, AP, accrued payroll, accrued liabilities, unearned revenue and other long-term liability lines, divided by the change in revenue: -0.8% (2021), +0.5% (2022), +4.9% (2023), +5.0% (2024), -7.2% (2025); 5-year average +0.5%. Income taxes payable and the operating lease asset/liability lines are excluded - taxes are handled inside NOPAT and leases are treated as an operating expense (see the WACC tab). Chipotle states in the FY2025 10-K that it 'has not required significant working capital because guests generally pay using cash or credit and debit cards' and it pays suppliers 'generally within ten days'.
A34: Memo: FY2021A-FY2025A actual (same definition) | B34: % | C34: =Historicals!C63 | D34: =Historicals!D63 | E34: =Historicals!E63 | F34: =Historicals!F63 | G34: =Historicals!G63
A36: FORECAST PERIOD AND TERMINAL ASSUMPTIONS
A37: Explicit forecast period | B37: years | C37: 5 | I37: FY2026E-FY2030E. Five years is long enough for the margin recovery to play out and short enough to stay credible.
A38: Terminal growth rate (g) | B38: % | C38: 0.0225 | I38: 2.25%, the midpoint of the 2.0-2.5% long-run U.S. nominal GDP / inflation anchor. Must be below WACC. A perpetual growth rate above nominal GDP would imply Chipotle eventually becomes the whole economy.
A39: Check: is g below WACC? (required, or the model breaks) | C39: =IF($C$38<WACC!$C$28,"OK - g is below WACC","ERROR - g must be below WACC")

Sheet WACC
A1: WACC - cost of capital via CAPM
A2: CALC | Chipotle carries no financial debt, so WACC collapses to the cost of equity. Lease treatment is stated explicitly below.
A4: COST OF EQUITY - CAPM: Re = Rf + beta x ERP
A5: Risk-free rate (Rf) - 10-year U.S. Treasury | B5: % | C5: 0.0478 | I5: U.S. Department of the Treasury, Daily Treasury Par Yield Curve Rates, 10-year constant maturity = 4.78% on 2026-09-04 (most recent published session). Retrieved 2026-09-06 from home.treasury.gov.
A6: Levered beta (CMG) | B6: x | C6: 0.94 | I6: stockanalysis.com/stocks/cmg/statistics/, 5-year monthly beta = 0.94; retrieved 2026-09-06. Because Chipotle carries no financial debt, its levered beta is effectively its unlevered beta - no re-levering is required.
A7: Equity risk premium (ERP) | B7: % | C7: 0.05 | I7: 5.0%, the low end of the 5.0-5.5% mature-market range commonly applied in practice. For reference, Damodaran's implied ERP for the S&P 500 on 2026-09-01 was 4.14% (trailing 12-month, adjusted payout; pages.stern.nyu.edu/~adamodar, retrieved 2026-09-06). Using 4.14% would lower the cost of equity by ~81bps and raise the implied value materially - flagged in README 'Open Items'.
A8: Cost of equity (Re) | B8: % | C8: =C5+C6*C7 | I8: Rf + beta x ERP.
A10: COST OF DEBT AND CAPITAL STRUCTURE
A11: CHIPOTLE HAS NO TRADITIONAL BORROWINGS. The FY2025 10-K (Note 12, Debt) discloses a $500.0m revolving credit facility with JPMorgan Chase that was UNDRAWN at 12/31/2025, and us-gaap:LongTermDebt is zero in every year FY2021-FY2025.
A12: Because the debt weight is ~0%, WACC in this model APPROXIMATES THE COST OF EQUITY. No debt tranche has been fabricated to make the formula look fuller.
A13: Total debt (D) | B13: $mm | C13: =Historicals!G70 | I13: Link to FY2025A total debt on the Historicals tab.
A14: Pre-tax cost of debt (Rd) - illustrative | B14: % | C14: 0.0538 | I14: Illustrative only, and it carries zero weight in the WACC because debt is zero. Set at the drawn rate on the undrawn revolver: SOFR + 1.125% per FY2025 10-K Note 12, proxied here with the 10-year Treasury of 4.78% + 60bps.
A15: Effective tax rate (t) | B15: % | C15: =Assumptions!C29 | I15: Link to the Assumptions tab.
A16: After-tax cost of debt = Rd x (1 - t) | B16: % | C16: =C14*(1-C15)
A18: MARKET CAPITALISATION AND WEIGHTS
A19: Current share price | B19: $ | C19: 36.96 | I19: stockanalysis.com/stocks/cmg/, closing price 2026-09-04 (last completed session); retrieved 2026-09-06.
A20: Shares outstanding at the valuation date | B20: mm | C20: 1302.423 | I20: FY2025 10-K cover page, dei:EntityCommonStockSharesOutstanding = 1,302,423,000 as of 2026-01-30 (the count closest to the 12/31/2025 valuation date). Post 50-for-1 split. The Q2 2026 10-Q cover reports 1,265,418,000 as of 2026-07-24 after further buybacks - see README 'Open Items'.
A21: Dilution factor (diluted / basic) | B21: x | C21: 1.00395 | I21: FY2025 diluted weighted-average shares (1,342,616k) / basic weighted-average shares (1,337,336k) = 1.00395, per the FY2025 10-K income statement. Applied to shares outstanding to approximate a fully diluted count.
A22: Diluted shares outstanding | B22: mm | C22: =C20*C21 | I22: Feeds the Valuation Bridge.
A23: Equity market capitalisation (E) | B23: $mm | C23: =C19*C22
A24: Weight of equity E / (D + E) | B24: % | C24: =C23/(C23+C13)
A25: Weight of debt D / (D + E) | B25: % | C25: =C13/(C23+C13)
A27: WACC
A28: WACC = E/(D+E) x Re + D/(D+E) x Rd x (1 - t) | B28: % | C28: =C24*C8+C25*C14*(1-C15)
A29: Does WACC equal the cost of equity? | C29: =IF(ABS(C28-C8)<0.0001,"Yes - debt weight is zero, so WACC = cost of equity","No - the company now carries debt")
A31: LEASE TREATMENT - STATED EXPLICITLY (this is a choice, and it must be consistent)
A32: TREATMENT USED IN THIS MODEL: operating leases are an OPERATING EXPENSE.
A33: 1. Occupancy cost stays inside EBIT (it is one of the four restaurant operating cost lines on the Historicals tab).
A34: 2. Operating lease liabilities are therefore EXCLUDED from net debt in the Valuation Bridge.
A35: 3. Because rent is never added back, the lease obligation is already captured in the cash flows being discounted. Deducting it again in the bridge would be double-counting.
A36: Operating lease liabilities at FY2025A (EXCLUDED from net debt) | B36: $mm | C36: =Historicals!G74 | I36: Shown so the number is visible, not hidden. It is NOT deducted in the bridge.
A38: THE ALTERNATIVE TREATMENT (know this for interviews): capitalise leases as debt.
A39: - Add rent expense back to EBIT, so EBIT and EBITDA rise.
A40: - Add a depreciation charge on the right-of-use asset and treat the interest component as financing.
A41: - Add the ~$5.1bn of lease liabilities to debt, which raises net debt and the debt weight in WACC.
A42: - Enterprise value rises, but so does the deduction in the bridge. Done correctly the two treatments should give a similar equity value - the error to avoid is a hybrid: keeping rent in EBIT AND deducting lease liabilities as debt, which double-counts and understates equity value by roughly $4/share here.
A44: MEMO: WHERE CMG TRADES TODAY (used to ground the exit multiple cross-check)
A45: Market enterprise value = market cap - cash and investments | B45: $mm | C45: =C23-Historicals!G69 | I45: Leases-as-opex basis, consistent with the rest of this model. Screeners that capitalise leases will show a materially higher EV.
A46: FY2025A EBITDA | B46: $mm | C46: =Historicals!G21
A47: Current EV / LTM EBITDA | B47: x | C47: =C45/C46

Sheet DCF
A1: DCF - unlevered free cash flow, FY2026E to FY2030E
A2: CALC | Revenue to UFCF to present value. Mid-year discounting convention is an explicit choice, set in a labelled input cell.
B4: Units | C4: FY2026E | D4: FY2027E | E4: FY2028E | F4: FY2029E | G4: FY2030E | I4: Source / note
A5: UNLEVERED FREE CASH FLOW BUILD ($ in millions)
A6: Revenue | B6: $mm | C6: =Assumptions!C18 | D6: =Assumptions!D18 | E6: =Assumptions!E18 | F6: =Assumptions!F18 | G6: =Assumptions!G18 | I6: Link to the Assumptions revenue build (average units x AUV).
A7: Revenue growth (YoY) | B7: % | C7: =C6/Historicals!G6-1 | D7: =D6/C6-1 | E7: =E6/D6-1 | F7: =F6/E6-1 | G7: =G6/F6-1
A8: EBIT margin | B8: % rev | C8: =Assumptions!C25 | D8: =Assumptions!D25 | E8: =Assumptions!E25 | F8: =Assumptions!F25 | G8: =Assumptions!G25
A9: Less: operating costs (implied by the margin assumption) | B9: $mm | C9: =-C6*(1-C8) | D9: =-D6*(1-D8) | E9: =-E6*(1-E8) | F9: =-F6*(1-F8) | G9: =-G6*(1-G8) | I9: Chipotle's cost structure is modelled at the EBIT-margin level rather than line by line; the Historicals tab shows every cost line as a % of revenue so the margin assumption is visibly grounded.
A10: EBIT | B10: $mm | C10: =C6+C9 | D10: =D6+D9 | E10: =E6+E9 | F10: =F6+F9 | G10: =G6+G9
A11: Effective tax rate | B11: % | C11: =Assumptions!$C$29 | D11: =Assumptions!$C$29 | E11: =Assumptions!$C$29 | F11: =Assumptions!$C$29 | G11: =Assumptions!$C$29
A12: Less: taxes on EBIT (unlevered) | B12: $mm | C12: =-C10*C11 | D12: =-D10*D11 | E12: =-E10*E11 | F12: =-F10*F11 | G12: =-G10*G11 | I12: Taxed on EBIT, not on pre-tax income - this is an UNLEVERED cash flow, so the interest tax shield is excluded (it lives in the WACC).
A13: NOPAT | B13: $mm | C13: =C10+C12 | D13: =D10+D12 | E13: =E10+E12 | F13: =F10+F12 | G13: =G10+G12
A14: D&A as % of revenue | B14: % rev | C14: =Assumptions!C30 | D14: =Assumptions!D30 | E14: =Assumptions!E30 | F14: =Assumptions!F30 | G14: =Assumptions!G30
A15: Plus: depreciation and amortisation | B15: $mm | C15: =C6*C14 | D15: =D6*D14 | E15: =E6*E14 | F15: =F6*F14 | G15: =G6*G14 | I15: Non-cash charge added back.
A16: CapEx as % of revenue | B16: % rev | C16: =Assumptions!C31 | D16: =Assumptions!D31 | E16: =Assumptions!E31 | F16: =Assumptions!F31 | G16: =Assumptions!G31
A17: Less: capital expenditures | B17: $mm | C17: =-C6*C16 | D17: =-D6*D16 | E17: =-E6*E16 | F17: =-F6*F16 | G17: =-G6*G16 | I17: New-unit construction plus maintenance and technology capex.
A18: Memo: change in revenue | B18: $mm | C18: =C6-Historicals!G6 | D18: =D6-C6 | E18: =E6-D6 | F18: =F6-E6 | G18: =G6-F6
A19: Change in NWC as % of change in revenue (+ = source) | B19: % | C19: =Assumptions!$C$33 | D19: =Assumptions!$C$33 | E19: =Assumptions!$C$33 | F19: =Assumptions!$C$33 | G19: =Assumptions!$C$33
A20: Plus / (less): change in net working capital | B20: $mm | C20: =C18*C19 | D20: =D18*D19 | E20: =E18*E19 | F20: =F18*F19 | G20: =G18*G19 | I20: POSITIVE here means working capital RELEASES cash. Chipotle runs negative working capital, so growth is a small source of cash, not a use. The sign is modelled as it actually behaves rather than assumed to be an outflow.
A21: UNLEVERED FREE CASH FLOW | B21: $mm | C21: =C13+C15+C17+C20 | D21: =D13+D15+D17+D20 | E21: =E13+E15+E17+E20 | F21: =F13+F15+F17+F20 | G21: =G13+G15+G17+G20
A22: UFCF margin | B22: % rev | C22: =C21/C6 | D22: =D21/D6 | E22: =E21/E6 | F22: =F21/F6 | G22: =G21/G6
A23: Memo: EBITDA (EBIT + D&A) | B23: $mm | C23: =C10+C15 | D23: =D10+D15 | E23: =E10+E15 | F23: =F10+F15 | G23: =G10+G15 | I23: Used by the exit-multiple cross-check on the Terminal Value tab.
A25: DISCOUNTING - MID-YEAR CONVENTION (an explicit choice, not a default)
A26: Cash flows are assumed to arrive evenly through the year rather than in a lump on 31 December, so each year is discounted from its midpoint: n = 0.5, 1.5, 2.5, 3.5, 4.5. State the convention out loud in an interview - assessors look for it.
A27: Worth knowing the magnitude: mid-year on the explicit cash flows alone is worth only +0.9% here ($20.12 vs $19.93), NOT the 4-5% usually quoted, because 78% of the value sits in the terminal value - which is discounted a full five periods either way. Moving the terminal value to n = 4.5 as well is worth a further +3.4%.
A28: Mid-year convention offset | B28: years | C28: 0.5 | I28: Set to 0.0 to switch the whole model to year-end discounting.
A29: Discount period (n) | B29: years | C29: =1-$C$28 | D29: =2-$C$28 | E29: =3-$C$28 | F29: =4-$C$28 | G29: =5-$C$28
A30: WACC | B30: % | C30: =WACC!C28
A31: Discount factor = 1 / (1 + WACC) ^ n | B31: x | C31: =1/(1+$C$30)^C29 | D31: =1/(1+$C$30)^D29 | E31: =1/(1+$C$30)^E29 | F31: =1/(1+$C$30)^F29 | G31: =1/(1+$C$30)^G29
A32: Present value of UFCF | B32: $mm | C32: =C21*C31 | D32: =D21*D31 | E32: =E21*E31 | F32: =F21*F31 | G32: =G21*G31
A33: Sum of PV of forecast UFCF (FY2026E-FY2030E) | B33: $mm | C33: =SUM(C32:G32)

Sheet Terminal Value
A1: TERMINAL VALUE - Gordon Growth, cross-checked against an exit multiple
A2: CALC | Primary method is Gordon Growth on a normalised terminal cash flow. The exit-multiple cross-check and the two implied-value checks are shown alongside.
A4: INPUTS CARRIED IN
A5: WACC | B5: % | C5: =WACC!C28
A6: Terminal growth rate (g) | B6: % | C6: =Assumptions!C38
A7: Spread (WACC - g) | B7: % | C7: =C5-C6 | I7: If this is not comfortably positive the Gordon Growth formula is meaningless.
A8: FY2030E revenue | B8: $mm | C8: =DCF!G6
A9: FY2030E NOPAT | B9: $mm | C9: =DCF!G13
A10: FY2030E D&A | B10: $mm | C10: =DCF!G15
A11: FY2030E capital expenditures | B11: $mm | C11: =DCF!G17 | I11: Negative, as presented on the DCF tab.
A12: FY2030E change in net working capital | B12: $mm | C12: =DCF!G20
A13: FY2030E unlevered free cash flow (as forecast) | B13: $mm | C13: =DCF!G21
A14: FY2030E EBITDA | B14: $mm | C14: =DCF!G23
A16: TERMINAL-YEAR NORMALISATION (why the raw year-5 cash flow cannot be used)
A17: FY2030E capex is 5.6% of revenue because the company is still opening ~370 restaurants a year. A perpetuity growing at 2.25% cannot also be spending at a 7%-unit-growth rate. Capex is therefore normalised to maintenance (= D&A) plus the growth capital needed to sustain 2.25% growth. Without this the terminal value is understated. Both versions are shown below.
A18: Normalised terminal capex as % of revenue | B18: % rev | C18: 0.038 | I18: Terminal-year normalisation. Year-5 capex of 5.6% of revenue supports ~7% unit growth and is inconsistent with a 2.25% perpetuity. Normalised to 3.8% = D&A of 3.1% of revenue (maintenance) plus ~0.7% of growth capital to sustain 2.25% growth. Without this adjustment the terminal value is understated. The unadjusted figure is shown alongside it on the Terminal Value tab.
A19: Normalised terminal capex | B19: $mm | C19: =-C8*C18
A20: NORMALISED TERMINAL UFCF | B20: $mm | C20: =C9+C10+C19+C12 | I20: NOPAT + D&A - normalised capex +/- change in NWC. This is the cash flow the Gordon Growth formula is applied to.
A22: METHOD 1 (PRIMARY): GORDON GROWTH - TV = FCF x (1 + g) / (WACC - g)
A23: Terminal value (Gordon Growth, normalised FCF) | B23: $mm | C23: =C20*(1+C6)/(C5-C6)
A24: Memo: same formula on the UNadjusted FY2030E UFCF | B24: $mm | C24: =C13*(1+C6)/(C5-C6) | I24: Shown for transparency. Lower, because it perpetuates growth-stage capex.
A26: METHOD 2 (CROSS-CHECK): EXIT MULTIPLE - TV = FY2030E EBITDA x exit EV/EBITDA
A27: Exit EV / EBITDA multiple | B27: x | C27: 18 | I27: Cross-check only. CMG currently trades at ~19.8x LTM EV/EBITDA on a leases-as-opex basis (EV of $45.5bn / FY2025 EBITDA of $2,297m; see the WACC and Terminal Value tabs where this is computed from market inputs). 18.0x applies a modest discount for multiple compression as unit growth decelerates.
A28: Memo: CMG's current EV / LTM EBITDA | B28: x | C28: =WACC!C47 | I28: Computed on the WACC tab from the current market cap and FY2025A EBITDA, leases-as-opex basis.
A29: Terminal value (exit multiple) | B29: $mm | C29: =C14*C27
A31: THE TWO CROSS-CHECKS THAT MATTER
A32: Implied exit EV/EBITDA from the Gordon Growth TV | B32: x | C32: =C23/C14 | I32: Gordon Growth terminal value divided by FY2030E EBITDA.
A33: Flag | C33: =IF(C32<10,"FLAG - below 10x. A GDP-anchored perpetuity implies a far lower exit multiple than CMG's current "&TEXT(C28,"0.0")&"x. Either the market is embedding growth well above GDP, or this WACC is too high.",IF(C32>25,"FLAG - above 25x, implausibly rich for a terminal multiple.","Reasonable - within the 10x-25x range for a mature restaurant operator."))
A34: Implied perpetuity growth from the exit-multiple TV | B34: % | C34: =(C29*C5-C20)/(C29+C20) | I34: Solves TV = FCF x (1+g) / (WACC - g) for g, holding the normalised terminal FCF constant.
A35: Flag | C35: =IF(C34>0.03,"FLAG - implies perpetual growth above ~3% nominal GDP, which is not sustainable. The exit multiple is doing the work, not the fundamentals.",IF(C34<0,"FLAG - implies perpetual decline.","Reasonable - consistent with long-run nominal GDP."))
A36: Interpretation: when these two checks disagree sharply, that IS the finding. The Gordon Growth answer says what the business is worth on GDP-anchored fundamentals; the exit multiple says what the market is currently willing to pay. The gap is the growth premium embedded in the share price.
A38: DISCOUNTING THE TERMINAL VALUE TO PRESENT VALUE
A39: Terminal value discount period (n) | B39: years | C39: 5 | I39: Terminal value is a year-5 year-END value, so it is discounted a full 5.0 periods even though the explicit cash flows use mid-year convention. Some practitioners use 4.5 for internal consistency with mid-year; that convention would raise the implied share price by 3.4% ($20.81 versus $20.12).
A40: Discount factor = 1 / (1 + WACC) ^ n | B40: x | C40: =1/(1+C5)^C39
A41: PRESENT VALUE OF TERMINAL VALUE | B41: $mm | C41: =C23*C40
A42: Memo: PV of the exit-multiple terminal value | B42: $mm | C42: =C29*C40
A44: HOW MUCH OF THE VALUE IS TERMINAL?
A45: Sum of PV of forecast UFCF | B45: $mm | C45: =DCF!C33
A46: Enterprise value | B46: $mm | C46: =C45+C41
A47: Terminal value as % of enterprise value | B47: % | C47: =C41/C46
...

Sheet Valuation Bridge
A1: VALUATION BRIDGE - enterprise value to implied share price
A2: OUTPUT | Sum of PV of forecast UFCF, plus PV of terminal value, less net debt, divided by diluted shares.
A4: ENTERPRISE VALUE TO IMPLIED SHARE PRICE ($ in millions, except per-share)
A5: Sum of PV of forecast UFCF (FY2026E-FY2030E) | B5: $mm | C5: =DCF!C33
A6: Plus: PV of terminal value | B6: $mm | C6: ='Terminal Value'!C41
A7: ENTERPRISE VALUE | B7: $mm | C7: =C5+C6
A8: Less: total debt | B8: $mm | C8: =-Historicals!G70 | I8: Zero. Chipotle's only facility is a $500m undrawn revolver (FY2025 10-K Note 12).
A9: Plus: cash and investments | B9: $mm | C9: =Historicals!G69 | I9: Cash and cash equivalents + short-term investments + long-term investments at 12/31/2025. Excludes $35.4m of restricted cash.
A10: Operating lease liabilities are NOT deducted | C10: Leases are treated as an operating expense, so occupancy cost is already inside EBIT. See the WACC tab.
A11: EQUITY VALUE | B11: $mm | C11: =C7+C8+C9
A12: Diluted shares outstanding | B12: mm | C12: =WACC!C22
A13: IMPLIED SHARE PRICE | B13: $ | C13: =C11/C12
A15: VERSUS THE MARKET
A16: Current market price | B16: $ | C16: =WACC!C19 | I16: stockanalysis.com/stocks/cmg/, closing price 2026-09-04 (last completed session); retrieved 2026-09-06.
A17: Implied upside / (downside) | B17: % | C17: =C13/C16-1
A18: Conclusion | C18: =IF(C17>0.15,"UNDERVALUED on these assumptions",IF(C17<-0.15,"OVERVALUED on these assumptions","FAIRLY VALUED - within +/-15%"))
A20: SANITY CHECKS - does the answer make sense?
A21: Implied EV / FY2025A EBITDA | B21: x | C21: =C7/Historicals!G21
A22: Implied EV / FY2030E EBITDA | B22: x | C22: =C7/DCF!G23
A23: Memo: EV the market is currently paying | B23: $mm | C23: =WACC!C45
A24: Memo: current EV / LTM EBITDA | B24: x | C24: =WACC!C47
A25: Gap: implied EV vs. market EV | B25: $mm | C25: =C7-C23 | I25: Negative means the market is paying more than this DCF supports. That gap is the thing to be able to explain in an interview.

Sheet Sensitivity
A1: SENSITIVITY - implied share price
A2: OUTPUT | Live formulas, not pasted values. Each cell re-runs the whole discounting and terminal-value calculation at that WACC / growth / margin pair.
A4: TABLE A - WACC (rows) x TERMINAL GROWTH (columns)
A5: Implied share price, $. Each cell re-discounts the five forecast UFCFs and rebuilds the terminal value at that WACC / g pair.
B7: WACC \ g | C7: 0.015 | D7: 0.0175 | E7: 0.02 | F7: 0.0225 | G7: 0.025 | H7: 0.0275 | I7: 0.03
B8: 0.0798 | C8: =IF($B8<=C$7+0.005,NA(),((DCF!$C$21/(1+$B8)^DCF!$C$29+DCF!$D$21/(1+$B8)^DCF!$D$29+DCF!$E$21/(1+$B8)^DCF!$E$29+DCF!$F$21/(1+$B8)^DCF!$F$29+DCF!$G$21/(1+$B8)^DCF!$G$29)+'Terminal Value'!$C$20*(1+C$7)/($B8-C$7)/(1+$B8)^'Terminal Value'!$C$39-Historicals!$G$70+Historicals!$G$69)/WACC!$C$22) | D8: =IF($B8<=D$7+0.005,NA(),((DCF!$C$21/(1+$B8)^DCF!$C$29+DCF!$D$21/(1+$B8)^DCF!$D$29+DCF!$E$21/(1+$B8)^DCF!$E$29+DCF!$F$21/(1+$B8)^DCF!$F$29+DCF!$G$21/(1+$B8)^DCF!$G$29)+'Terminal Value'!$C$20*(1+D$7)/($B8-D$7)/(1+$B8)^'Terminal Value'!$C$39-Historicals!$G$70+Historicals!$G$69)/WACC!$C$22) | E8: =IF($B8<=E$7+0.005,NA(),((DCF!$C$21/(1+$B8)^DCF!$C$29+DCF!$D$21/(1+$B8)^DCF!$D$29+DCF!$E$21/(1+$B8)^DCF!$E$29+DCF!$F$21/(1+$B8)^DCF!$F$29+DCF!$G$21/(1+$B8)^DCF!$G$29)+'Terminal Value'!$C$20*(1+E$7)/($B8-E$7)/(1+$B8)^'Terminal Value'!$C$39-Historicals!$G$70+Historicals!$G$69)/WACC!$C$22) | F8: =IF($B8<=F$7+0.005,NA(),((DCF!$C$21/(1+$B8)^DCF!$C$29+DCF!$D$21/(1+$B8)^DCF!$D$29+DCF!$E$21/(1+$B8)^DCF!$E$29+DCF!$F$21/(1+$B8)^DCF!$F$29+DCF!$G$21/(1+$B8)^DCF!$G$29)+'Terminal Value'!$C$20*(1+F$7)/($B8-F$7)/(1+$B8)^'Terminal Value'!$C$39-Historicals!$G$70+Historicals!$G$69)/WACC!$C$22) | G8: =IF($B8<=G$7+0.005,NA(),((DCF!$C$21/(1+$B8)^DCF!$C$29+DCF!$D$21/(1+$B8)^DCF!$D$29+DCF!$E$21/(1+$B8)^DCF!$E$29+DCF!$F$21/(1+$B8)^DCF!$F$29+DCF!$G$21/(1+$B8)^DCF!$G$29)+'Terminal Value'!$C$20*(1+G$7)/($B8-G$7)/(1+$B8)^'Terminal Value'!$C$39-Historicals!$G$70+Historicals!$G$69)/WACC!$C$22) | H8: =IF($B8<=H$7+0.005,NA(),((DCF!$C$21/(1+$B8)^DCF!$C$29+DCF!$D$21/(1+$B8)^DCF!$D$29+DCF!$E$21/(1+$B8)^DCF!$E$29+DCF!$F$21/(1+$B8)^DCF!$F$29+DCF!$G$21/(1+$B8)^DCF!$G$29)+'Terminal Value'!$C$20*(1+H$7)/($B8-H$7)/(1+$B8)^'Terminal Value'!$C$39-Historicals!$G$70+Historicals!$G$69)/WACC!$C$22) | I8: =IF($B8<=I$7+0.005,NA(),((DCF!$C$21/(1+$B8)^DCF!$C$29+DCF!$D$21/(1+$B8)^DCF!$D$29+DCF!$E$21/(1+$B8)^DCF!$E$29+DCF!$F$21/(1+$B8)^DCF!$F$29+DCF!$G$21/(1+$B8)^DCF!$G$29)+'Terminal Value'!$C$20*(1+I$7)/($B8-I$7)/(1+$B8)^'Terminal Value'!$C$39-Historicals!$G$70+Historicals!$G$69)/WACC!$C$22)
B9: 0.0823 | C9: =IF($B9<=C$7+0.005,NA(),((DCF!$C$21/(1+$B9)^DCF!$C$29+DCF!$D$21/(1+$B9)^DCF!$D$29+DCF!$E$21/(1+$B9)^DCF!$E$29+DCF!$F$21/(1+$B9)^DCF!$F$29+DCF!$G$21/(1+$B9)^DCF!$G$29)+'Terminal Value'!$C$20*(1+C$7)/($B9-C$7)/(1+$B9)^'Terminal Value'!$C$39-Historicals!$G$70+Historicals!$G$69)/WACC!$C$22) | D9: =IF($B9<=D$7+0.005,NA(),((DCF!$C$21/(1+$B9)^DCF!$C$29+DCF!$D$21/(1+$B9)^DCF!$D$29+DCF!$E$21/(1+$B9)^DCF!$E$29+DCF!$F$21/(1+$B9)^DCF!$F$29+DCF!$G$21/(1+$B9)^DCF!$G$29)+'Terminal Value'!$C$20*(1+D$7)/($B9-D$7)/(1+$B9)^'Terminal Value'!$C$39-Historicals!$G$70+Historicals!$G$69)/WACC!$C$22) | E9: =IF($B9<=E$7+0.005,NA(),((DCF!$C$21/(1+$B9)^DCF!$C$29+DCF!$D$21/(1+$B9)^DCF!$D$29+DCF!$E$21/(1+$B9)^DCF!$E$29+DCF!$F$21/(1+$B9)^DCF!$F$29+DCF!$G$21/(1+$B9)^DCF!$G$29)+'Terminal Value'!$C$20*(1+E$7)/($B9-E$7)/(1+$B9)^'Terminal Value'!$C$39-Historicals!$G$70+Historicals!$G$69)/WACC!$C$22) | F9: =IF($B9<=F$7+0.005,NA(),((DCF!$C$21/(1+$B9)^DCF!$C$29+DCF!$D$21/(1+$B9)^DCF!$D$29+DCF!$E$21/(1+$B9)^DCF!$E$29+DCF!$F$21/(1+$B9)^DCF!$F$29+DCF!$G$21/(1+$B9)^DCF!$G$29)+'Terminal Value'!$C$20*(1+F$7)/($B9-F$7)/(1+$B9)^'Terminal Value'!$C$39-Historicals!$G$70+Historicals!$G$69)/WACC!$C$22) | G9: =IF($B9<=G$7+0.005,NA(),((DCF!$C$21/(1+$B9)^DCF!$C$29+DCF!$D$21/(1+$B9)^DCF!$D$29+DCF!$E$21/(1+$B9)^DCF!$E$29+DCF!$F$21/(1+$B9)^DCF!$F$29+DCF!$G$21/(1+$B9)^DCF!$G$29)+'Terminal Value'!$C$20*(1+G$7)/($B9-G$7)/(1+$B9)^'Terminal Value'!$C$39-Historicals!$G$70+Historicals!$G$69)/WACC!$C$22) | H9: =IF($B9<=H$7+0.005,NA(),((DCF!$C$21/(1+$B9)^DCF!$C$29+DCF!$D$21/(1+$B9)^DCF!$D$29+DCF!$E$21/(1+$B9)^DCF!$E$29+DCF!$F$21/(1+$B9)^DCF!$F$29+DCF!$G$21/(1+$B9)^DCF!$G$29)+'Terminal Value'!$C$20*(1+H$7)/($B9-H$7)/(1+$B9)^'Terminal Value'!$C$39-Historicals!$G$70+Historicals!$G$69)/WACC!$C$22) | I9: =IF($B9<=I$7+0.005,NA(),((DCF!$C$21/(1+$B9)^DCF!$C$29+DCF!$D$21/(1+$B9)^DCF!$D$29+DCF!$E$21/(1+$B9)^DCF!$E$29+DCF!$F$21/(1+$B9)^DCF!$F$29+DCF!$G$21/(1+$B9)^DCF!$G$29)+'Terminal Value'!$C$20*(1+I$7)/($B9-I$7)/(1+$B9)^'Terminal Value'!$C$39-Historicals!$G$70+Historicals!$G$69)/WACC!$C$22)
B10: 0.0848 | C10: =IF($B10<=C$7+0.005,NA(),((DCF!$C$21/(1+$B10)^DCF!$C$29+DCF!$D$21/(1+$B10)^DCF!$D$29+DCF!$E$21/(1+$B10)^DCF!$E$29+DCF!$F$21/(1+$B10)^DCF!$F$29+DCF!$G$21/(1+$B10)^DCF!$G$29)+'Terminal Value'!$C$20*(1+C$7)/($B10-C$7)/(1+$B10)^'Terminal Value'!$C$39-Historicals!$G$70+Historicals!$G$69)/WACC!$C$22) | D10: =IF($B10<=D$7+0.005,NA(),((DCF!$C$21/(1+$B10)^DCF!$C$29+DCF!$D$21/(1+$B10)^DCF!$D$29+DCF!$E$21/(1+$B10)^DCF!$E$29+DCF!$F$21/(1+$B10)^DCF!$F$29+DCF!$G$21/(1+$B10)^DCF!$G$29)+'Terminal Value'!$C$20*(1+D$7)/($B10-D$7)/(1+$B10)^'Terminal Value'!$C$39-Historicals!$G$70+Historicals!$G$69)/WACC!$C$22) | E10: =IF($B10<=E$7+0.005,NA(),((DCF!$C$21/(1+$B10)^DCF!$C$29+DCF!$D$21/(1+$B10)^DCF!$D$29+DCF!$E$21/(1+$B10)^DCF!$E$29+DCF!$F$21/(1+$B10)^DCF!$F$29+DCF!$G$21/(1+$B10)^DCF!$G$29)+'Terminal Value'!$C$20*(1+E$7)/($B10-E$7)/(1+$B10)^'Terminal Value'!$C$39-Historicals!$G$70+Historicals!$G$69)/WACC!$C$22) | F10: =IF($B10<=F$7+0.005,NA(),((DCF!$C$21/(1+$B10)^DCF!$C$29+DCF!$D$21/(1+$B10)^DCF!$D$29+DCF!$E$21/(1+$B10)^DCF!$E$29+DCF!$F$21/(1+$B10)^DCF!$F$29+DCF!$G$21/(1+$B10)^DCF!$G$29)+'Terminal Value'!$C$20*(1+F$7)/($B10-F$7)/(1+$B10)^'Terminal Value'!$C$39-Historicals!$G$70+Historicals!$G$69)/WACC!$C$22) | G10: =IF($B10<=G$7+0.005,NA(),((DCF!$C$21/(1+$B10)^DCF!$C$29+DCF!$D$21/(1+$B10)^DCF!$D$29+DCF!$E$21/(1+$B10)^DCF!$E$29+DCF!$F$21/(1+$B10)^DCF!$F$29+DCF!$G$21/(1+$B10)^DCF!$G$29)+'Terminal Value'!$C$20*(1+G$7)/($B10-G$7)/(1+$B10)^'Terminal Value'!$C$39-Historicals!$G$70+Historicals!$G$69)/WACC!$C$22) | H10: =IF($B10<=H$7+0.005,NA(),((DCF!$C$21/(1+$B10)^DCF!$C$29+DCF!$D$21/(1+$B10)^DCF!$D$29+DCF!$E$21/(1+$B10)^DCF!$E$29+DCF!$F$21/(1+$B10)^DCF!$F$29+DCF!$G$21/(1+$B10)^DCF!$G$29)+'Terminal Value'!$C$20*(1+H$7)/($B10-H$7)/(1+$B10)^'Terminal Value'!$C$39-Historicals!$G$70+Historicals!$G$69)/WACC!$C$22) | I10: =IF($B10<=I$7+0.005,NA(),((DCF!$C$21/(1+$B10)^DCF!$C$29+DCF!$D$21/(1+$B10)^DCF!$D$29+DCF!$E$21/(1+$B10)^DCF!$E$29+DCF!$F$21/(1+$B10)^DCF!$F$29+DCF!$G$21/(1+$B10)^DCF!$G$29)+'Terminal Value'!$C$20*(1+I$7)/($B10-I$7)/(1+$B10)^'Terminal Value'!$C$39-Historicals!$G$70+Historicals!$G$69)/WACC!$C$22)
B11: 0.0873 | C11: =IF($B11<=C$7+0.005,NA(),((DCF!$C$21/(1+$B11)^DCF!$C$29+DCF!$D$21/(1+$B11)^DCF!$D$29+DCF!$E$21/(1+$B11)^DCF!$E$29+DCF!$F$21/(1+$B11)^DCF!$F$29+DCF!$G$21/(1+$B11)^DCF!$G$29)+'Terminal Value'!$C$20*(1+C$7)/($B11-C$7)/(1+$B11)^'Terminal Value'!$C$39-Historicals!$G$70+Historicals!$G$69)/WACC!$C$22) | D11: =IF($B11<=D$7+0.005,NA(),((DCF!$C$21/(1+$B11)^DCF!$C$29+DCF!$D$21/(1+$B11)^DCF!$D$29+DCF!$E$21/(1+$B11)^DCF!$E$29+DCF!$F$21/(1+$B11)^DCF!$F$29+DCF!$G$21/(1+$B11)^DCF!$G$29)+'Terminal Value'!$C$20*(1+D$7)/($B11-D$7)/(1+$B11)^'Terminal Value'!$C$39-Historicals!$G$70+Historicals!$G$69)/WACC!$C$22) | E11: =IF($B11<=E$7+0.005,NA(),((DCF!$C$21/(1+$B11)^DCF!$C$29+DCF!$D$21/(1+$B11)^DCF!$D$29+DCF!$E$21/(1+$B11)^DCF!$E$29+DCF!$F$21/(1+$B11)^DCF!$F$29+DCF!$G$21/(1+$B11)^DCF!$G$29)+'Terminal Value'!$C$20*(1+E$7)/($B11-E$7)/(1+$B11)^'Terminal Value'!$C$39-Historicals!$G$70+Historicals!$G$69)/WACC!$C$22) | F11: =IF($B11<=F$7+0.005,NA(),((DCF!$C$21/(1+$B11)^DCF!$C$29+DCF!$D$21/(1+$B11)^DCF!$D$29+DCF!$E$21/(1+$B11)^DCF!$E$29+DCF!$F$21/(1+$B11)^DCF!$F$29+DCF!$G$21/(1+$B11)^DCF!$G$29)+'Terminal Value'!$C$20*(1+F$7)/($B11-F$7)/(1+$B11)^'Terminal Value'!$C$39-Historicals!$G$70+Historicals!$G$69)/WACC!$C$22) | G11: =IF($B11<=G$7+0.005,NA(),((DCF!$C$21/(1+$B11)^DCF!$C$29+DCF!$D$21/(1+$B11)^DCF!$D$29+DCF!$E$21/(1+$B11)^DCF!$E$29+DCF!$F$21/(1+$B11)^DCF!$F$29+DCF!$G$21/(1+$B11)^DCF!$G$29)+'Terminal Value'!$C$20*(1+G$7)/($B11-G$7)/(1+$B11)^'Terminal Value'!$C$39-Historicals!$G$70+Historicals!$G$69)/WACC!$C$22) | H11: =IF($B11<=H$7+0.005,NA(),((DCF!$C$21/(1+$B11)^DCF!$C$29+DCF!$D$21/(1+$B11)^DCF!$D$29+DCF!$E$21/(1+$B11)^DCF!$E$29+DCF!$F$21/(1+$B11)^DCF!$F$29+DCF!$G$21/(1+$B11)^DCF!$G$29)+'Terminal Value'!$C$20*(1+H$7)/($B11-H$7)/(1+$B11)^'Terminal Value'!$C$39-Historicals!$G$70+Historicals!$G$69)/WACC!$C$22) | I11: =IF($B11<=I$7+0.005,NA(),((DCF!$C$21/(1+$B11)^DCF!$C$29+DCF!$D$21/(1+$B11)^DCF!$D$29+DCF!$E$21/(1+$B11)^DCF!$E$29+DCF!$F$21/(1+$B11)^DCF!$F$29+DCF!$G$21/(1+$B11)^DCF!$G$29)+'Terminal Value'!$C$20*(1+I$7)/($B11-I$7)/(1+$B11)^'Terminal Value'!$C$39-Historicals!$G$70+Historicals!$G$69)/WACC!$C$22)
B12: 0.0898 | C12: =IF($B12<=C$7+0.005,NA(),((DCF!$C$21/(1+$B12)^DCF!$C$29+DCF!$D$21/(1+$B12)^DCF!$D$29+DCF!$E$21/(1+$B12)^DCF!$E$29+DCF!$F$21/(1+$B12)^DCF!$F$29+DCF!$G$21/(1+$B12)^DCF!$G$29)+'Terminal Value'!$C$20*(1+C$7)/($B12-C$7)/(1+$B12)^'Terminal Value'!$C$39-Historicals!$G$70+Historicals!$G$69)/WACC!$C$22) | D12: =IF($B12<=D$7+0.005,NA(),((DCF!$C$21/(1+$B12)^DCF!$C$29+DCF!$D$21/(1+$B12)^DCF!$D$29+DCF!$E$21/(1+$B12)^DCF!$E$29+DCF!$F$21/(1+$B12)^DCF!$F$29+DCF!$G$21/(1+$B12)^DCF!$G$29)+'Terminal Value'!$C$20*(1+D$7)/($B12-D$7)/(1+$B12)^'Terminal Value'!$C$39-Historicals!$G$70+Historicals!$G$69)/WACC!$C$22) | E12: =IF($B12<=E$7+0.005,NA(),((DCF!$C$21/(1+$B12)^DCF!$C$29+DCF!$D$21/(1+$B12)^DCF!$D$29+DCF!$E$21/(1+$B12)^DCF!$E$29+DCF!$F$21/(1+$B12)^DCF!$F$29+DCF!$G$21/(1+$B12)^DCF!$G$29)+'Terminal Value'!$C$20*(1+E$7)/($B12-E$7)/(1+$B12)^'Terminal Value'!$C$39-Historicals!$G$70+Historicals!$G$69)/WACC!$C$22) | F12: =IF($B12<=F$7+0.005,NA(),((DCF!$C$21/(1+$B12)^DCF!$C$29+DCF!$D$21/(1+$B12)^DCF!$D$29+DCF!$E$21/(1+$B12)^DCF!$E$29+DCF!$F$21/(1+$B12)^DCF!$F$29+DCF!$G$21/(1+$B12)^DCF!$G$29)+'Terminal Value'!$C$20*(1+F$7)/($B12-F$7)/(1+$B12)^'Terminal Value'!$C$39-Historicals!$G$70+Historicals!$G$69)/WACC!$C$22) | G12: =IF($B12<=G$7+0.005,NA(),((DCF!$C$21/(1+$B12)^DCF!$C$29+DCF!$D$21/(1+$B12)^DCF!$D$29+DCF!$E$21/(1+$B12)^DCF!$E$29+DCF!$F$21/(1+$B12)^DCF!$F$29+DCF!$G$21/(1+$B12)^DCF!$G$29)+'Terminal Value'!$C$20*(1+G$7)/($B12-G$7)/(1+$B12)^'Terminal Value'!$C$39-Historicals!$G$70+Historicals!$G$69)/WACC!$C$22) | H12: =IF($B12<=H$7+0.005,NA(),((DCF!$C$21/(1+$B12)^DCF!$C$29+DCF!$D$21/(1+$B12)^DCF!$D$29+DCF!$E$21/(1+$B12)^DCF!$E$29+DCF!$F$21/(1+$B12)^DCF!$F$29+DCF!$G$21/(1+$B12)^DCF!$G$29)+'Terminal Value'!$C$20*(1+H$7)/($B12-H$7)/(1+$B12)^'Terminal Value'!$C$39-Historicals!$G$70+Historicals!$G$69)/WACC!$C$22) | I12: =IF($B12<=I$7+0.005,NA(),((DCF!$C$21/(1+$B12)^DCF!$C$29+DCF!$D$21/(1+$B12)^DCF!$D$29+DCF!$E$21/(1+$B12)^DCF!$E$29+DCF!$F$21/(1+$B12)^DCF!$F$29+DCF!$G$21/(1+$B12)^DCF!$G$29)+'Terminal Value'!$C$20*(1+I$7)/($B12-I$7)/(1+$B12)^'Terminal Value'!$C$39-Historicals!$G$70+Historicals!$G$69)/WACC!$C$22)
B13: 0.0923 | C13: =IF($B13<=C$7+0.005,NA(),((DCF!$C$21/(1+$B13)^DCF!$C$29+DCF!$D$21/(1+$B13)^DCF!$D$29+DCF!$E$21/(1+$B13)^DCF!$E$29+DCF!$F$21/(1+$B13)^DCF!$F$29+DCF!$G$21/(1+$B13)^DCF!$G$29)+'Terminal Value'!$C$20*(1+C$7)/($B13-C$7)/(1+$B13)^'Terminal Value'!$C$39-Historicals!$G$70+Historicals!$G$69)/WACC!$C$22) | D13: =IF($B13<=D$7+0.005,NA(),((DCF!$C$21/(1+$B13)^DCF!$C$29+DCF!$D$21/(1+$B13)^DCF!$D$29+DCF!$E$21/(1+$B13)^DCF!$E$29+DCF!$F$21/(1+$B13)^DCF!$F$29+DCF!$G$21/(1+$B13)^DCF!$G$29)+'Terminal Value'!$C$20*(1+D$7)/($B13-D$7)/(1+$B13)^'Terminal Value'!$C$39-Historicals!$G$70+Historicals!$G$69)/WACC!$C$22) | E13: =IF($B13<=E$7+0.005,NA(),((DCF!$C$21/(1+$B13)^DCF!$C$29+DCF!$D$21/(1+$B13)^DCF!$D$29+DCF!$E$21/(1+$B13)^DCF!$E$29+DCF!$F$21/(1+$B13)^DCF!$F$29+DCF!$G$21/(1+$B13)^DCF!$G$29)+'Terminal Value'!$C$20*(1+E$7)/($B13-E$7)/(1+$B13)^'Terminal Value'!$C$39-Historicals!$G$70+Historicals!$G$69)/WACC!$C$22) | F13: =IF($B13<=F$7+0.005,NA(),((DCF!$C$21/(1+$B13)^DCF!$C$29+DCF!$D$21/(1+$B13)^DCF!$D$29+DCF!$E$21/(1+$B13)^DCF!$E$29+DCF!$F$21/(1+$B13)^DCF!$F$29+DCF!$G$21/(1+$B13)^DCF!$G$29)+'Terminal Value'!$C$20*(1+F$7)/($B13-F$7)/(1+$B13)^'Terminal Value'!$C$39-Historicals!$G$70+Historicals!$G$69)/WACC!$C$22) | G13: =IF($B13<=G$7+0.005,NA(),((DCF!$C$21/(1+$B13)^DCF!$C$29+DCF!$D$21/(1+$B13)^DCF!$D$29+DCF!$E$21/(1+$B13)^DCF!$E$29+DCF!$F$21/(1+$B13)^DCF!$F$29+DCF!$G$21/(1+$B13)^DCF!$G$29)+'Terminal Value'!$C$20*(1+G$7)/($B13-G$7)/(1+$B13)^'Terminal Value'!$C$39-Historicals!$G$70+Historicals!$G$69)/WACC!$C$22) | H13: =IF($B13<=H$7+0.005,NA(),((DCF!$C$21/(1+$B13)^DCF!$C$29+DCF!$D$21/(1+$B13)^DCF!$D$29+DCF!$E$21/(1+$B13)^DCF!$E$29+DCF!$F$21/(1+$B13)^DCF!$F$29+DCF!$G$21/(1+$B13)^DCF!$G$29)+'Terminal Value'!$C$20*(1+H$7)/($B13-H$7)/(1+$B13)^'Terminal Value'!$C$39-Historicals!$G$70+Historicals!$G$69)/WACC!$C$22) | I13: =IF($B13<=I$7+0.005,NA(),((DCF!$C$21/(1+$B13)^DCF!$C$29+DCF!$D$21/(1+$B13)^DCF!$D$29+DCF!$E$21/(1+$B13)^DCF!$E$29+DCF!$F$21/(1+$B13)^DCF!$F$29+DCF!$G$21/(1+$B13)^DCF!$G$29)+'Terminal Value'!$C$20*(1+I$7)/($B13-I$7)/(1+$B13)^'Terminal Value'!$C$39-Historicals!$G$70+Historicals!$G$69)/WACC!$C$22)
B14: 0.0948 | C14: =IF($B14<=C$7+0.005,NA(),((DCF!$C$21/(1+$B14)^DCF!$C$29+DCF!$D$21/(1+$B14)^DCF!$D$29+DCF!$E$21/(1+$B14)^DCF!$E$29+DCF!$F$21/(1+$B14)^DCF!$F$29+DCF!$G$21/(1+$B14)^DCF!$G$29)+'Terminal Value'!$C$20*(1+C$7)/($B14-C$7)/(1+$B14)^'Terminal Value'!$C$39-Historicals!$G$70+Historicals!$G$69)/WACC!$C$22) | D14: =IF($B14<=D$7+0.005,NA(),((DCF!$C$21/(1+$B14)^DCF!$C$29+DCF!$D$21/(1+$B14)^DCF!$D$29+DCF!$E$21/(1+$B14)^DCF!$E$29+DCF!$F$21/(1+$B14)^DCF!$F$29+DCF!$G$21/(1+$B14)^DCF!$G$29)+'Terminal Value'!$C$20*(1+D$7)/($B14-D$7)/(1+$B14)^'Terminal Value'!$C$39-Historicals!$G$70+Historicals!$G$69)/WACC!$C$22) | E14: =IF($B14<=E$7+0.005,NA(),((DCF!$C$21/(1+$B14)^DCF!$C$29+DCF!$D$21/(1+$B14)^DCF!$D$29+DCF!$E$21/(1+$B14)^DCF!$E$29+DCF!$F$21/(1+$B14)^DCF!$F$29+DCF!$G$21/(1+$B14)^DCF!$G$29)+'Terminal Value'!$C$20*(1+E$7)/($B14-E$7)/(1+$B14)^'Terminal Value'!$C$39-Historicals!$G$70+Historicals!$G$69)/WACC!$C$22) | F14: =IF($B14<=F$7+0.005,NA(),((DCF!$C$21/(1+$B14)^DCF!$C$29+DCF!$D$21/(1+$B14)^DCF!$D$29+DCF!$E$21/(1+$B14)^DCF!$E$29+DCF!$F$21/(1+$B14)^DCF!$F$29+DCF!$G$21/(1+$B14)^DCF!$G$29)+'Terminal Value'!$C$20*(1+F$7)/($B14-F$7)/(1+$B14)^'Terminal Value'!$C$39-Historicals!$G$70+Historicals!$G$69)/WACC!$C$22) | G14: =IF($B14<=G$7+0.005,NA(),((DCF!$C$21/(1+$B14)^DCF!$C$29+DCF!$D$21/(1+$B14)^DCF!$D$29+DCF!$E$21/(1+$B14)^DCF!$E$29+DCF!$F$21/(1+$B14)^DCF!$F$29+DCF!$G$21/(1+$B14)^DCF!$G$29)+'Terminal Value'!$C$20*(1+G$7)/($B14-G$7)/(1+$B14)^'Terminal Value'!$C$39-Historicals!$G$70+Historicals!$G$69)/WACC!$C$22) | H14: =IF($B14<=H$7+0.005,NA(),((DCF!$C$21/(1+$B14)^DCF!$C$29+DCF!$D$21/(1+$B14)^DCF!$D$29+DCF!$E$21/(1+$B14)^DCF!$E$29+DCF!$F$21/(1+$B14)^DCF!$F$29+DCF!$G$21/(1+$B14)^DCF!$G$29)+'Terminal Value'!$C$20*(1+H$7)/($B14-H$7)/(1+$B14)^'Terminal Value'!$C$39-Historicals!$G$70+Historicals!$G$69)/WACC!$C$22) | I14: =IF($B14<=I$7+0.005,NA(),((DCF!$C$21/(1+$B14)^DCF!$C$29+DCF!$D$21/(1+$B14)^DCF!$D$29+DCF!$E$21/(1+$B14)^DCF!$E$29+DCF!$F$21/(1+$B14)^DCF!$F$29+DCF!$G$21/(1+$B14)^DCF!$G$29)+'Terminal Value'!$C$20*(1+I$7)/($B14-I$7)/(1+$B14)^'Terminal Value'!$C$39-Historicals!$G$70+Historicals!$G$69)/WACC!$C$22)
B15: 0.0973 | C15: =IF($B15<=C$7+0.005,NA(),((DCF!$C$21/(1+$B15)^DCF!$C$29+DCF!$D$21/(1+$B15)^DCF!$D$29+DCF!$E$21/(1+$B15)^DCF!$E$29+DCF!$F$21/(1+$B15)^DCF!$F$29+DCF!$G$21/(1+$B15)^DCF!$G$29)+'Terminal Value'!$C$20*(1+C$7)/($B15-C$7)/(1+$B15)^'Terminal Value'!$C$39-Historicals!$G$70+Historicals!$G$69)/WACC!$C$22) | D15: =IF($B15<=D$7+0.005,NA(),((DCF!$C$21/(1+$B15)^DCF!$C$29+DCF!$D$21/(1+$B15)^DCF!$D$29+DCF!$E$21/(1+$B15)^DCF!$E$29+DCF!$F$21/(1+$B15)^DCF!$F$29+DCF!$G$21/(1+$B15)^DCF!$G$29)+'Terminal Value'!$C$20*(1+D$7)/($B15-D$7)/(1+$B15)^'Terminal Value'!$C$39-Historicals!$G$70+Historicals!$G$69)/WACC!$C$22) | E15: =IF($B15<=E$7+0.005,NA(),((DCF!$C$21/(1+$B15)^DCF!$C$29+DCF!$D$21/(1+$B15)^DCF!$D$29+DCF!$E$21/(1+$B15)^DCF!$E$29+DCF!$F$21/(1+$B15)^DCF!$F$29+DCF!$G$21/(1+$B15)^DCF!$G$29)+'Terminal Value'!$C$20*(1+E$7)/($B15-E$7)/(1+$B15)^'Terminal Value'!$C$39-Historicals!$G$70+Historicals!$G$69)/WACC!$C$22) | F15: =IF($B15<=F$7+0.005,NA(),((DCF!$C$21/(1+$B15)^DCF!$C$29+DCF!$D$21/(1+$B15)^DCF!$D$29+DCF!$E$21/(1+$B15)^DCF!$E$29+DCF!$F$21/(1+$B15)^DCF!$F$29+DCF!$G$21/(1+$B15)^DCF!$G$29)+'Terminal Value'!$C$20*(1+F$7)/($B15-F$7)/(1+$B15)^'Terminal Value'!$C$39-Historicals!$G$70+Historicals!$G$69)/WACC!$C$22) | G15: =IF($B15<=G$7+0.005,NA(),((DCF!$C$21/(1+$B15)^DCF!$C$29+DCF!$D$21/(1+$B15)^DCF!$D$29+DCF!$E$21/(1+$B15)^DCF!$E$29+DCF!$F$21/(1+$B15)^DCF!$F$29+DCF!$G$21/(1+$B15)^DCF!$G$29)+'Terminal Value'!$C$20*(1+G$7)/($B15-G$7)/(1+$B15)^'Terminal Value'!$C$39-Historicals!$G$70+Historicals!$G$69)/WACC!$C$22) | H15: =IF($B15<=H$7+0.005,NA(),((DCF!$C$21/(1+$B15)^DCF!$C$29+DCF!$D$21/(1+$B15)^DCF!$D$29+DCF!$E$21/(1+$B15)^DCF!$E$29+DCF!$F$21/(1+$B15)^DCF!$F$29+DCF!$G$21/(1+$B15)^DCF!$G$29)+'Terminal Value'!$C$20*(1+H$7)/($B15-H$7)/(1+$B15)^'Terminal Value'!$C$39-Historicals!$G$70+Historicals!$G$69)/WACC!$C$22) | I15: =IF($B15<=I$7+0.005,NA(),((DCF!$C$21/(1+$B15)^DCF!$C$29+DCF!$D$21/(1+$B15)^DCF!$D$29+DCF!$E$21/(1+$B15)^DCF!$E$29+DCF!$F$21/(1+$B15)^DCF!$F$29+DCF!$G$21/(1+$B15)^DCF!$G$29)+'Terminal Value'!$C$20*(1+I$7)/($B15-I$7)/(1+$B15)^'Terminal Value'!$C$39-Historicals!$G$70+Historicals!$G$69)/WACC!$C$22)
B16: 0.0998 | C16: =IF($B16<=C$7+0.005,NA(),((DCF!$C$21/(1+$B16)^DCF!$C$29+DCF!$D$21/(1+$B16)^DCF!$D$29+DCF!$E$21/(1+$B16)^DCF!$E$29+DCF!$F$21/(1+$B16)^DCF!$F$29+DCF!$G$21/(1+$B16)^DCF!$G$29)+'Terminal Value'!$C$20*(1+C$7)/($B16-C$7)/(1+$B16)^'Terminal Value'!$C$39-Historicals!$G$70+Historicals!$G$69)/WACC!$C$22) | D16: =IF($B16<=D$7+0.005,NA(),((DCF!$C$21/(1+$B16)^DCF!$C$29+DCF!$D$21/(1+$B16)^DCF!$D$29+DCF!$E$21/(1+$B16)^DCF!$E$29+DCF!$F$21/(1+$B16)^DCF!$F$29+DCF!$G$21/(1+$B16)^DCF!$G$29)+'Terminal Value'!$C$20*(1+D$7)/($B16-D$7)/(1+$B16)^'Terminal Value'!$C$39-Historicals!$G$70+Historicals!$G$69)/WACC!$C$22) | E16: =IF($B16<=E$7+0.005,NA(),((DCF!$C$21/(1+$B16)^DCF!$C$29+DCF!$D$21/(1+$B16)^DCF!$D$29+DCF!$E$21/(1+$B16)^DCF!$E$29+DCF!$F$21/(1+$B16)^DCF!$F$29+DCF!$G$21/(1+$B16)^DCF!$G$29)+'Terminal Value'!$C$20*(1+E$7)/($B16-E$7)/(1+$B16)^'Terminal Value'!$C$39-Historicals!$G$70+Historicals!$G$69)/WACC!$C$22) | F16: =IF($B16<=F$7+0.005,NA(),((DCF!$C$21/(1+$B16)^DCF!$C$29+DCF!$D$21/(1+$B16)^DCF!$D$29+DCF!$E$21/(1+$B16)^DCF!$E$29+DCF!$F$21/(1+$B16)^DCF!$F$29+DCF!$G$21/(1+$B16)^DCF!$G$29)+'Terminal Value'!$C$20*(1+F$7)/($B16-F$7)/(1+$B16)^'Terminal Value'!$C$39-Historicals!$G$70+Historicals!$G$69)/WACC!$C$22) | G16: =IF($B16<=G$7+0.005,NA(),((DCF!$C$21/(1+$B16)^DCF!$C$29+DCF!$D$21/(1+$B16)^DCF!$D$29+DCF!$E$21/(1+$B16)^DCF!$E$29+DCF!$F$21/(1+$B16)^DCF!$F$29+DCF!$G$21/(1+$B16)^DCF!$G$29)+'Terminal Value'!$C$20*(1+G$7)/($B16-G$7)/(1+$B16)^'Terminal Value'!$C$39-Historicals!$G$70+Historicals!$G$69)/WACC!$C$22) | H16: =IF($B16<=H$7+0.005,NA(),((DCF!$C$21/(1+$B16)^DCF!$C$29+DCF!$D$21/(1+$B16)^DCF!$D$29+DCF!$E$21/(1+$B16)^DCF!$E$29+DCF!$F$21/(1+$B16)^DCF!$F$29+DCF!$G$21/(1+$B16)^DCF!$G$29)+'Terminal Value'!$C$20*(1+H$7)/($B16-H$7)/(1+$B16)^'Terminal Value'!$C$39-Historicals!$G$70+Historicals!$G$69)/WACC!$C$22) | I16: =IF($B16<=I$7+0.005,NA(),((DCF!$C$21/(1+$B16)^DCF!$C$29+DCF!$D$21/(1+$B16)^DCF!$D$29+DCF!$E$21/(1+$B16)^DCF!$E$29+DCF!$F$21/(1+$B16)^DCF!$F$29+DCF!$G$21/(1+$B16)^DCF!$G$29)+'Terminal Value'!$C$20*(1+I$7)/($B16-I$7)/(1+$B16)^'Terminal Value'!$C$39-Historicals!$G$70+Historicals!$G$69)/WACC!$C$22)
B17: 0.1023 | C17: =IF($B17<=C$7+0.005,NA(),((DCF!$C$21/(1+$B17)^DCF!$C$29+DCF!$D$21/(1+$B17)^DCF!$D$29+DCF!$E$21/(1+$B17)^DCF!$E$29+DCF!$F$21/(1+$B17)^DCF!$F$29+DCF!$G$21/(1+$B17)^DCF!$G$29)+'Terminal Value'!$C$20*(1+C$7)/($B17-C$7)/(1+$B17)^'Terminal Value'!$C$39-Historicals!$G$70+Historicals!$G$69)/WACC!$C$22) | D17: =IF($B17<=D$7+0.005,NA(),((DCF!$C$21/(1+$B17)^DCF!$C$29+DCF!$D$21/(1+$B17)^DCF!$D$29+DCF!$E$21/(1+$B17)^DCF!$E$29+DCF!$F$21/(1+$B17)^DCF!$F$29+DCF!$G$21/(1+$B17)^DCF!$G$29)+'Terminal Value'!$C$20*(1+D$7)/($B17-D$7)/(1+$B17)^'Terminal Value'!$C$39-Historicals!$G$70+Historicals!$G$69)/WACC!$C$22) | E17: =IF($B17<=E$7+0.005,NA(),((DCF!$C$21/(1+$B17)^DCF!$C$29+DCF!$D$21/(1+$B17)^DCF!$D$29+DCF!$E$21/(1+$B17)^DCF!$E$29+DCF!$F$21/(1+$B17)^DCF!$F$29+DCF!$G$21/(1+$B17)^DCF!$G$29)+'Terminal Value'!$C$20*(1+E$7)/($B17-E$7)/(1+$B17)^'Terminal Value'!$C$39-Historicals!$G$70+Historicals!$G$69)/WACC!$C$22) | F17: =IF($B17<=F$7+0.005,NA(),((DCF!$C$21/(1+$B17)^DCF!$C$29+DCF!$D$21/(1+$B17)^DCF!$D$29+DCF!$E$21/(1+$B17)^DCF!$E$29+DCF!$F$21/(1+$B17)^DCF!$F$29+DCF!$G$21/(1+$B17)^DCF!$G$29)+'Terminal Value'!$C$20*(1+F$7)/($B17-F$7)/(1+$B17)^'Terminal Value'!$C$39-Historicals!$G$70+Historicals!$G$69)/WACC!$C$22) | G17: =IF($B17<=G$7+0.005,NA(),((DCF!$C$21/(1+$B17)^DCF!$C$29+DCF!$D$21/(1+$B17)^DCF!$D$29+DCF!$E$21/(1+$B17)^DCF!$E$29+DCF!$F$21/(1+$B17)^DCF!$F$29+DCF!$G$21/(1+$B17)^DCF!$G$29)+'Terminal Value'!$C$20*(1+G$7)/($B17-G$7)/(1+$B17)^'Terminal Value'!$C$39-Historicals!$G$70+Historicals!$G$69)/WACC!$C$22) | H17: =IF($B17<=H$7+0.005,NA(),((DCF!$C$21/(1+$B17)^DCF!$C$29+DCF!$D$21/(1+$B17)^DCF!$D$29+DCF!$E$21/(1+$B17)^DCF!$E$29+DCF!$F$21/(1+$B17)^DCF!$F$29+DCF!$G$21/(1+$B17)^DCF!$G$29)+'Terminal Value'!$C$20*(1+H$7)/($B17-H$7)/(1+$B17)^'Terminal Value'!$C$39-Historicals!$G$70+Historicals!$G$69)/WACC!$C$22) | I17: =IF($B17<=I$7+0.005,NA(),((DCF!$C$21/(1+$B17)^DCF!$C$29+DCF!$D$21/(1+$B17)^DCF!$D$29+DCF!$E$21/(1+$B17)^DCF!$E$29+DCF!$F$21/(1+$B17)^DCF!$F$29+DCF!$G$21/(1+$B17)^DCF!$G$29)+'Terminal Value'!$C$20*(1+I$7)/($B17-I$7)/(1+$B17)^'Terminal Value'!$C$39-Historicals!$G$70+Historicals!$G$69)/WACC!$C$22)
B18: 0.1048 | C18: =IF($B18<=C$7+0.005,NA(),((DCF!$C$21/(1+$B18)^DCF!$C$29+DCF!$D$21/(1+$B18)^DCF!$D$29+DCF!$E$21/(1+$B18)^DCF!$E$29+DCF!$F$21/(1+$B18)^DCF!$F$29+DCF!$G$21/(1+$B18)^DCF!$G$29)+'Terminal Value'!$C$20*(1+C$7)/($B18-C$7)/(1+$B18)^'Terminal Value'!$C$39-Historicals!$G$70+Historicals!$G$69)/WACC!$C$22) | D18: =IF($B18<=D$7+0.005,NA(),((DCF!$C$21/(1+$B18)^DCF!$C$29+DCF!$D$21/(1+$B18)^DCF!$D$29+DCF!$E$21/(1+$B18)^DCF!$E$29+DCF!$F$21/(1+$B18)^DCF!$F$29+DCF!$G$21/(1+$B18)^DCF!$G$29)+'Terminal Value'!$C$20*(1+D$7)/($B18-D$7)/(1+$B18)^'Terminal Value'!$C$39-Historicals!$G$70+Historicals!$G$69)/WACC!$C$22) | E18: =IF($B18<=E$7+0.005,NA(),((DCF!$C$21/(1+$B18)^DCF!$C$29+DCF!$D$21/(1+$B18)^DCF!$D$29+DCF!$E$21/(1+$B18)^DCF!$E$29+DCF!$F$21/(1+$B18)^DCF!$F$29+DCF!$G$21/(1+$B18)^DCF!$G$29)+'Terminal Value'!$C$20*(1+E$7)/($B18-E$7)/(1+$B18)^'Terminal Value'!$C$39-Historicals!$G$70+Historicals!$G$69)/WACC!$C$22) | F18: =IF($B18<=F$7+0.005,NA(),((DCF!$C$21/(1+$B18)^DCF!$C$29+DCF!$D$21/(1+$B18)^DCF!$D$29+DCF!$E$21/(1+$B18)^DCF!$E$29+DCF!$F$21/(1+$B18)^DCF!$F$29+DCF!$G$21/(1+$B18)^DCF!$G$29)+'Terminal Value'!$C$20*(1+F$7)/($B18-F$7)/(1+$B18)^'Terminal Value'!$C$39-Historicals!$G$70+Historicals!$G$69)/WACC!$C$22) | G18: =IF($B18<=G$7+0.005,NA(),((DCF!$C$21/(1+$B18)^DCF!$C$29+DCF!$D$21/(1+$B18)^DCF!$D$29+DCF!$E$21/(1+$B18)^DCF!$E$29+DCF!$F$21/(1+$B18)^DCF!$F$29+DCF!$G$21/(1+$B18)^DCF!$G$29)+'Terminal Value'!$C$20*(1+G$7)/($B18-G$7)/(1+$B18)^'Terminal Value'!$C$39-Historicals!$G$70+Historicals!$G$69)/WACC!$C$22) | H18: =IF($B18<=H$7+0.005,NA(),((DCF!$C$21/(1+$B18)^DCF!$C$29+DCF!$D$21/(1+$B18)^DCF!$D$29+DCF!$E$21/(1+$B18)^DCF!$E$29+DCF!$F$21/(1+$B18)^DCF!$F$29+DCF!$G$21/(1+$B18)^DCF!$G$29)+'Terminal Value'!$C$20*(1+H$7)/($B18-H$7)/(1+$B18)^'Terminal Value'!$C$39-Historicals!$G$70+Historicals!$G$69)/WACC!$C$22) | I18: =IF($B18<=I$7+0.005,NA(),((DCF!$C$21/(1+$B18)^DCF!$C$29+DCF!$D$21/(1+$B18)^DCF!$D$29+DCF!$E$21/(1+$B18)^DCF!$E$29+DCF!$F$21/(1+$B18)^DCF!$F$29+DCF!$G$21/(1+$B18)^DCF!$G$29)+'Terminal Value'!$C$20*(1+I$7)/($B18-I$7)/(1+$B18)^'Terminal Value'!$C$39-Historicals!$G$70+Historicals!$G$69)/WACC!$C$22)
